Workbook

Sheet Instructions
B1: Platform Engineering Maturity Scorecard
B2: Version 1.0 — 2026 Edition | The Comprehensive Guide to Platform Engineering
B4: HOW TO USE THIS SCORECARD
B5: Step 1 | C5: Complete the Assessment Questionnaire (assessment-questionnaire.md) honestly.
B6: Step 2 | C6: On the 'Domain Scores' sheet, enter your answer for each question using the drop-down (A through E or F).
B7: Step 3 | C7: The scorecard automatically calculates your domain scores, composite maturity level, and gap analysis.
B8: Step 4 | C8: Review the Radar Chart sheet to see your capability profile visually.
B9: Step 5 | C9: Use the Improvement Roadmap sheet to plan your next 90-day sprint.
B11: SCORING SCALE
B12: Answer A | C12: Level 0 — Fragmented Infrastructure
B13: Answer B | C13: Level 1 — Standardised Tooling
B14: Answer C | C14: Level 2 — CI/CD Automation
B15: Answer D | C15: Level 3–4 — Platform Foundations / Self-Service
B16: Answer E | C16: Level 5 — Platform as Product
B17: Answer F | C17: Level 6 — Autonomous Platform (where applicable)
B19: IMPORTANT NOTES
B20: Honest answers | C20: Score what exists and works today, not what is in progress or planned.
B21: Evidence rule | C21: For any score of Level 4+, you must be able to cite a concrete recent example.
B22: Ceiling effects | C22: Gaps in any domain create ceiling effects on overall platform maturity.
B23: Reassessment | C23: Reassess quarterly. Trajectory matters as much as absolute score.

Sheet Domain Scores
B1: Platform Engineering Maturity Scorecard — Domain Assessment
B2: Domain | C2: Question ID | D2: Question Summary | E2: Your Answer (A–F) | F2: Level Score (0–6) | G2: Target Level | H2: Gap | I2: Notes
B3: D1 Infrastructure & Provisioning | C3: D1-Q1 | D3: How is infrastructure provisioned? | F3: =IF(E3="A",0,IF(E3="B",1,IF(E3="C",2,IF(E3="D",3,IF(E3="E",5,IF(E3="F",6,"")))))) | G3: 4 | H3: =IF(F3="","",G3-F3)
C4: D1-Q2 | D4: How are cloud environments managed? | F4: =IF(E4="A",0,IF(E4="B",1,IF(E4="C",2,IF(E4="D",3,IF(E4="E",5,IF(E4="F",6,"")))))) | G4: 4 | H4: =IF(F4="","",G4-F4)
C5: D1-Q3 | D5: How is infrastructure drift managed? | F5: =IF(E5="A",0,IF(E5="B",1,IF(E5="C",2,IF(E5="D",3,IF(E5="E",5,IF(E5="F",6,"")))))) | G5: 4 | H5: =IF(F5="","",G5-F5)
C6: D1-Q4 | D6: How are new cloud accounts managed? | F6: =IF(E6="A",0,IF(E6="B",1,IF(E6="C",2,IF(E6="D",3,IF(E6="E",5,IF(E6="F",6,"")))))) | G6: 4 | H6: =IF(F6="","",G6-F6)
C7: D1-Q5 | D7: What is your IaC module strategy? | F7: =IF(E7="A",0,IF(E7="B",1,IF(E7="C",2,IF(E7="D",3,IF(E7="E",5,IF(E7="F",6,"")))))) | G7: 4 | H7: =IF(F7="","",G7-F7)
B8: D1 — Infrastructure & Provisioning — Domain Average | F8: =IFERROR(AVERAGE(F3:F7),"")
B10: D2 Delivery & Deployment | C10: D2-Q1 | D10: How do teams build and deploy services? | F10: =IF(E10="A",0,IF(E10="B",1,IF(E10="C",2,IF(E10="D",3,IF(E10="E",5,IF(E10="F",6,"")))))) | G10: 4 | H10: =IF(F10="","",G10-F10)
C11: D2-Q2 | D11: What is your typical deployment frequency? | F11: =IF(E11="A",0,IF(E11="B",1,IF(E11="C",2,IF(E11="D",3,IF(E11="E",5,IF(E11="F",6,"")))))) | G11: 4 | H11: =IF(F11="","",G11-F11)
C12: D2-Q3 | D12: How are production changes governed? | F12: =IF(E12="A",0,IF(E12="B",1,IF(E12="C",2,IF(E12="D",3,IF(E12="E",5,IF(E12="F",6,"")))))) | G12: 4 | H12: =IF(F12="","",G12-F12)
C13: D2-Q4 | D13: What progressive delivery capabilities exist? | F13: =IF(E13="A",0,IF(E13="B",1,IF(E13="C",2,IF(E13="D",3,IF(E13="E",5,IF(E13="F",6,"")))))) | G13: 4 | H13: =IF(F13="","",G13-F13)
C14: D2-Q5 | D14: How is delivery performance tracked? | F14: =IF(E14="A",0,IF(E14="B",1,IF(E14="C",2,IF(E14="D",3,IF(E14="E",5,IF(E14="F",6,"")))))) | G14: 4 | H14: =IF(F14="","",G14-F14)
B15: D2 — Delivery & Deployment — Domain Average | F15: =IFERROR(AVERAGE(F10:F14),"")
B17: D3 Developer Experience | C17: D3-Q1 | D17: How do developers discover platform capabilities? | F17: =IF(E17="A",0,IF(E17="B",1,IF(E17="C",2,IF(E17="D",3,IF(E17="E",5,IF(E17="F",6,"")))))) | G17: 4 | H17: =IF(F17="","",G17-F17)
C18: D3-Q2 | D18: Time to first production commit for new engineers? | F18: =IF(E18="A",0,IF(E18="B",1,IF(E18="C",2,IF(E18="D",3,IF(E18="E",5,IF(E18="F",6,"")))))) | G18: 4 | H18: =IF(F18="","",G18-F18)
C19: D3-Q3 | D19: How are new services created? | F19: =IF(E19="A",0,IF(E19="B",1,IF(E19="C",2,IF(E19="D",3,IF(E19="E",5,IF(E19="F",6,"")))))) | G19: 4 | H19: =IF(F19="","",G19-F19)
C20: D3-Q4 | D20: How do developers work locally? | F20: =IF(E20="A",0,IF(E20="B",1,IF(E20="C",2,IF(E20="D",3,IF(E20="E",5,IF(E20="F",6,"")))))) | G20: 4 | H20: =IF(F20="","",G20-F20)
C21: D3-Q5 | D21: How is developer satisfaction measured? | F21: =IF(E21="A",0,IF(E21="B",1,IF(E21="C",2,IF(E21="D",3,IF(E21="E",5,IF(E21="F",6,"")))))) | G21: 4 | H21: =IF(F21="","",G21-F21)
B22: D3 — Developer Experience — Domain Average | F22: =IFERROR(AVERAGE(F17:F21),"")
B24: D4 Observability | C24: D4-Q1 | D24: What telemetry does the platform provide? | F24: =IF(E24="A",0,IF(E24="B",1,IF(E24="C",2,IF(E24="D",3,IF(E24="E",5,IF(E24="F",6,"")))))) | G24: 4 | H24: =IF(F24="","",G24-F24)
C25: D4-Q2 | D25: How are SLOs managed across services? | F25: =IF(E25="A",0,IF(E25="B",1,IF(E25="C",2,IF(E25="D",3,IF(E25="E",5,IF(E25="F",6,"")))))) | G25: 4 | H25: =IF(F25="","",G25-F25)
C26: D4-Q3 | D26: What is your average MTTR? | F26: =IF(E26="A",0,IF(E26="B",1,IF(E26="C",2,IF(E26="D",3,IF(E26="E",5,IF(E26="F",6,"")))))) | G26: 4 | H26: =IF(F26="","",G26-F26)
C27: D4-Q4 | D27: How is alerting managed? | F27: =IF(E27="A",0,IF(E27="B",1,IF(E27="C",2,IF(E27="D",3,IF(E27="E",5,IF(E27="F",6,"")))))) | G27: 4 | H27: =IF(F27="","",G27-F27)
C28: D4-Q5 | D28: How is observability infrastructure managed? | F28: =IF(E28="A",0,IF(E28="B",1,IF(E28="C",2,IF(E28="D",3,IF(E28="E",5,IF(E28="F",6,"")))))) | G28: 4 | H28: =IF(F28="","",G28-F28)
B29: D4 — Observability — Domain Average | F29: =IFERROR(AVERAGE(F24:F28),"")
B31: D5 Security & Compliance | C31: D5-Q1 | D31: How are secrets managed? | F31: =IF(E31="A",0,IF(E31="B",1,IF(E31="C",2,IF(E31="D",3,IF(E31="E",5,IF(E31="F",6,"")))))) | G31: 4 | H31: =IF(F31="","",G31-F31)
C32: D5-Q2 | D32: How is policy enforced? | F32: =IF(E32="A",0,IF(E32="B",1,IF(E32="C",2,IF(E32="D",3,IF(E32="E",5,IF(E32="F",6,"")))))) | G32: 4 | H32: =IF(F32="","",G32-F32)
C33: D5-Q3 | D33: What is your supply chain security posture? | F33: =IF(E33="A",0,IF(E33="B",1,IF(E33="C",2,IF(E33="D",3,IF(E33="E",5,IF(E33="F",6,"")))))) | G33: 4 | H33: =IF(F33="","",G33-F33)
C34: D5-Q4 | D34: How is production access managed? | F34: =IF(E34="A",0,IF(E34="B",1,IF(E34="C",2,IF(E34="D",3,IF(E34="E",5,IF(E34="F",6,"")))))) | G34: 4 | H34: =IF(F34="","",G34-F34)
C35: D5-Q5 | D35: How is compliance managed? | F35: =IF(E35="A",0,IF(E35="B",1,IF(E35="C",2,IF(E35="D",3,IF(E35="E",5,IF(E35="F",6,"")))))) | G35: 4 | H35: =IF(F35="","",G35-F35)
B36: D5 — Security & Compliance — Domain Average | F36: =IFERROR(AVERAGE(F31:F35),"")
B38: D6 FinOps & Cost Management | C38: D6-Q1 | D38: What cloud cost visibility exists? | F38: =IF(E38="A",0,IF(E38="B",1,IF(E38="C",2,IF(E38="D",3,IF(E38="E",5,IF(E38="F",6,"")))))) | G38: 4 | H38: =IF(F38="","",G38-F38)
C39: D6-Q2 | D39: How are costs allocated to teams? | F39: =IF(E39="A",0,IF(E39="B",1,IF(E39="C",2,IF(E39="D",3,IF(E39="E",5,IF(E39="F",6,"")))))) | G39: 4 | H39: =IF(F39="","",G39-F39)
C40: D6-Q3 | D40: How is rightsizing managed? | F40: =IF(E40="A",0,IF(E40="B",1,IF(E40="C",2,IF(E40="D",3,IF(E40="E",5,IF(E40="F",6,"")))))) | G40: 4 | H40: =IF(F40="","",G40-F40)
C41: D6-Q4 | D41: Is there a FinOps function? | F41: =IF(E41="A",0,IF(E41="B",1,IF(E41="C",2,IF(E41="D",3,IF(E41="E",5,IF(E41="F",6,"")))))) | G41: 4 | H41: =IF(F41="","",G41-F41)
C42: D6-Q5 | D42: How is cloud waste managed? | F42: =IF(E42="A",0,IF(E42="B",1,IF(E42="C",2,IF(E42="D",3,IF(E42="E",5,IF(E42="F",6,"")))))) | G42: 4 | H42: =IF(F42="","",G42-F42)
B43: D6 — FinOps & Cost Management — Domain Average | F43: =IFERROR(AVERAGE(F38:F42),"")
B45: D7 Organisational Model | C45: D7-Q1 | D45: How is the platform team structured? | F45: =IF(E45="A",0,IF(E45="B",1,IF(E45="C",2,IF(E45="D",3,IF(E45="E",5,IF(E45="F",6,"")))))) | G45: 4 | H45: =IF(F45="","",G45-F45)
C46: D7-Q2 | D46: How is the platform roadmap managed? | F46: =IF(E46="A",0,IF(E46="B",1,IF(E46="C",2,IF(E46="D",3,IF(E46="E",5,IF(E46="F",6,"")))))) | G46: 4 | H46: =IF(F46="","",G46-F46)
...

Sheet Summary Dashboard
B1: Platform Engineering Maturity — Summary Dashboard
B2: Organisation: Assessment Date: Assessed By:
B4: DOMAIN MATURITY SCORES
B5: Domain | C5: Weight | D5: Current Level (0–6) | E5: Target Level | F5: Gap | G5: Status
B6: D1 — Infrastructure & Provisioning | C6: 0.15 | D6: ='Domain Scores'!F8 | E6: 4 | F6: =IFERROR(E6-D6,"") | G6: =IFERROR(IF(F6<=0,"✓ On Target",IF(F6<=1,"▲ Near Target","✗ Gap — Action Required")),"—")
B7: D2 — Delivery & Deployment | C7: 0.15 | D7: ='Domain Scores'!F15 | E7: 4 | F7: =IFERROR(E7-D7,"") | G7: =IFERROR(IF(F7<=0,"✓ On Target",IF(F7<=1,"▲ Near Target","✗ Gap — Action Required")),"—")
B8: D3 — Developer Experience | C8: 0.2 | D8: ='Domain Scores'!F22 | E8: 4 | F8: =IFERROR(E8-D8,"") | G8: =IFERROR(IF(F8<=0,"✓ On Target",IF(F8<=1,"▲ Near Target","✗ Gap — Action Required")),"—")
B9: D4 — Observability | C9: 0.12 | D9: ='Domain Scores'!F29 | E9: 4 | F9: =IFERROR(E9-D9,"") | G9: =IFERROR(IF(F9<=0,"✓ On Target",IF(F9<=1,"▲ Near Target","✗ Gap — Action Required")),"—")
B10: D5 — Security & Compliance | C10: 0.12 | D10: ='Domain Scores'!F36 | E10: 4 | F10: =IFERROR(E10-D10,"") | G10: =IFERROR(IF(F10<=0,"✓ On Target",IF(F10<=1,"▲ Near Target","✗ Gap — Action Required")),"—")
B11: D6 — FinOps & Cost Management | C11: 0.08 | D11: ='Domain Scores'!F43 | E11: 4 | F11: =IFERROR(E11-D11,"") | G11: =IFERROR(IF(F11<=0,"✓ On Target",IF(F11<=1,"▲ Near Target","✗ Gap — Action Required")),"—")
B12: D7 — Organisational Model | C12: 0.13 | D12: ='Domain Scores'!F50 | E12: 4 | F12: =IFERROR(E12-D12,"") | G12: =IFERROR(IF(F12<=0,"✓ On Target",IF(F12<=1,"▲ Near Target","✗ Gap — Action Required")),"—")
B13: D8 — AI & Automation | C13: 0.05 | D13: ='Domain Scores'!F57 | E13: 4 | F13: =IFERROR(E13-D13,"") | G13: =IFERROR(IF(F13<=0,"✓ On Target",IF(F13<=1,"▲ Near Target","✗ Gap — Action Required")),"—")
B15: COMPOSITE MATURITY SCORE (Weighted) | D15: =IFERROR(D6*0.15+D7*0.15+D8*0.2+D9*0.12+D10*0.12+D11*0.08+D12*0.13+D13*0.05,"")
B17: OVERALL MATURITY LEVEL | D17: =IFERROR(IF(D15<0.5,"Level 0 — Fragmented Infrastructure",IF(D15<1.5,"Level 1 — Standardised Tooling",IF(D15<2.5,"Level 2 — CI/CD Automation",IF(D15<3.5,"Level 3 — Platform Foundations",IF(D15<4.5,"Level 4 — Self-Service Platform",IF(D15<5.5,"Level 5 — Platform as Product","Level 6 — Autonomous Platform")))))),"")
B19: MATURITY LEVEL REFERENCE
B20: Level 0 | C20: Fragmented Infrastructure | D20: No shared platform. Manual, inconsistent, high risk.
B21: Level 1 | C21: Standardised Tooling | D21: Common tools mandated. Compliance improving. High toil.
B22: Level 2 | C22: CI/CD Automation | D22: Repeatable delivery pipelines. Platform team still on critical path.
B23: Level 3 | C23: Platform Foundations | D23: Core IDP exists. Self-service for golden paths. Portal live.
B24: Level 4 | C24: Self-Service Platform | D24: Developers independent for common workflows. Platform team enabling, not doing.
B25: Level 5 | C25: Platform as Product | D25: SLAs, NPS, PM, roadmap. Developer experience as a product discipline.
B26: Level 6 | C26: Autonomous Platform | D26: AI-augmented operations. Platform self-maintains and self-optimises.

Sheet Radar Chart
B1: Domain | C1: Current Level | D1: Target Level
B2: D1 Infra | C2: ='Summary Dashboard'!D6 | D2: ='Summary Dashboard'!E6
B3: D2 Delivery | C3: ='Summary Dashboard'!D7 | D3: ='Summary Dashboard'!E7
B4: D3 DX | C4: ='Summary Dashboard'!D8 | D4: ='Summary Dashboard'!E8
B5: D4 Observability | C5: ='Summary Dashboard'!D9 | D5: ='Summary Dashboard'!E9
B6: D5 Security | C6: ='Summary Dashboard'!D10 | D6: ='Summary Dashboard'!E10
B7: D6 FinOps | C7: ='Summary Dashboard'!D11 | D7: ='Summary Dashboard'!E11
B8: D7 Org Model | C8: ='Summary Dashboard'!D12 | D8: ='Summary Dashboard'!E12
B9: D8 AI | C9: ='Summary Dashboard'!D13 | D9: ='Summary Dashboard'!E13
B11: Note: Populate the Domain Scores sheet to see the radar chart update automatically.

Sheet Gap Analysis
B1: Platform Maturity — Gap & Priority Analysis
B2: Domains sorted by gap size (largest gap first). Focus investment on high-weight, high-gap domains.
B4: Domain | C4: Weight | D4: Current Level | E4: Target Level | F4: Gap Score | G4: Priority Recommendation
B5: D1 — Infrastructure & Provisioning | C5: ='Summary Dashboard'!C6 | D5: ='Summary Dashboard'!D6 | E5: ='Summary Dashboard'!E6 | F5: ='Summary Dashboard'!F6 | G5: =IF(F5="","—",IF(F5>=2,"🔴 Critical — address this quarter",IF(F5>=1,"🟡 High — address this half-year",IF(F5>0,"🟢 Low — address within 12 months","✓ On or ahead of target"))))
B6: D2 — Delivery & Deployment | C6: ='Summary Dashboard'!C7 | D6: ='Summary Dashboard'!D7 | E6: ='Summary Dashboard'!E7 | F6: ='Summary Dashboard'!F7 | G6: =IF(F6="","—",IF(F6>=2,"🔴 Critical — address this quarter",IF(F6>=1,"🟡 High — address this half-year",IF(F6>0,"🟢 Low — address within 12 months","✓ On or ahead of target"))))
B7: D3 — Developer Experience | C7: ='Summary Dashboard'!C8 | D7: ='Summary Dashboard'!D8 | E7: ='Summary Dashboard'!E8 | F7: ='Summary Dashboard'!F8 | G7: =IF(F7="","—",IF(F7>=2,"🔴 Critical — address this quarter",IF(F7>=1,"🟡 High — address this half-year",IF(F7>0,"🟢 Low — address within 12 months","✓ On or ahead of target"))))
B8: D4 — Observability | C8: ='Summary Dashboard'!C9 | D8: ='Summary Dashboard'!D9 | E8: ='Summary Dashboard'!E9 | F8: ='Summary Dashboard'!F9 | G8: =IF(F8="","—",IF(F8>=2,"🔴 Critical — address this quarter",IF(F8>=1,"🟡 High — address this half-year",IF(F8>0,"🟢 Low — address within 12 months","✓ On or ahead of target"))))
B9: D5 — Security & Compliance | C9: ='Summary Dashboard'!C10 | D9: ='Summary Dashboard'!D10 | E9: ='Summary Dashboard'!E10 | F9: ='Summary Dashboard'!F10 | G9: =IF(F9="","—",IF(F9>=2,"🔴 Critical — address this quarter",IF(F9>=1,"🟡 High — address this half-year",IF(F9>0,"🟢 Low — address within 12 months","✓ On or ahead of target"))))
B10: D6 — FinOps & Cost Management | C10: ='Summary Dashboard'!C11 | D10: ='Summary Dashboard'!D11 | E10: ='Summary Dashboard'!E11 | F10: ='Summary Dashboard'!F11 | G10: =IF(F10="","—",IF(F10>=2,"🔴 Critical — address this quarter",IF(F10>=1,"🟡 High — address this half-year",IF(F10>0,"🟢 Low — address within 12 months","✓ On or ahead of target"))))
B11: D7 — Organisational Model | C11: ='Summary Dashboard'!C12 | D11: ='Summary Dashboard'!D12 | E11: ='Summary Dashboard'!E12 | F11: ='Summary Dashboard'!F12 | G11: =IF(F11="","—",IF(F11>=2,"🔴 Critical — address this quarter",IF(F11>=1,"🟡 High — address this half-year",IF(F11>0,"🟢 Low — address within 12 months","✓ On or ahead of target"))))
B12: D8 — AI & Automation | C12: ='Summary Dashboard'!C13 | D12: ='Summary Dashboard'!D13 | E12: ='Summary Dashboard'!E13 | F12: ='Summary Dashboard'!F13 | G12: =IF(F12="","—",IF(F12>=2,"🔴 Critical — address this quarter",IF(F12>=1,"🟡 High — address this half-year",IF(F12>0,"🟢 Low — address within 12 months","✓ On or ahead of target"))))
B14: CEILING CONSTRAINT ANALYSIS
B15: ▸ Domains scoring below Level 2 create ceiling effects across the entire platform — fix these first regardless of weight.
B16: ▸ D3 (Developer Experience) gaps are amplified: low DX adoption undermines investment in all other domains.
B17: ▸ D7 (Organisational Model) gaps above Level 3 prevent sustainable progress — technical capability without product thinking stalls.
B18: ▸ D8 (AI & Automation) gaps are lower priority at Level 0-3; prioritise once core platform foundations are stable.
